I0128 19:43:31.288779  2784 datasets.py:9] Preparing dataset HAPT...
Traceback (most recent call last):
  File "D:\HAR\pythonProject\main.py", line 54, in <module>
    app.run(main)
  File "D:\miniconda\envs\jndata\lib\site-packages\absl\app.py", line 308, in run
    _run_main(main, args)
  File "D:\miniconda\envs\jndata\lib\site-packages\absl\app.py", line 254, in _run_main
    sys.exit(main(argv))
  File "D:\HAR\pythonProject\main.py", line 48, in main
    evaluate(model,
  File "D:\HAR\pythonProject\evaluation\eval.py", line 39, in evaluate
    for test_images, test_labels in ds_test:
  File "D:\miniconda\envs\jndata\lib\site-packages\tensorflow\python\data\ops\iterator_ops.py", line 766, in __next__
    return self._next_internal()
  File "D:\miniconda\envs\jndata\lib\site-packages\tensorflow\python\data\ops\iterator_ops.py", line 749, in _next_internal
    ret = gen_dataset_ops.iterator_get_next(
  File "D:\miniconda\envs\jndata\lib\site-packages\tensorflow\python\ops\gen_dataset_ops.py", line 3011, in iterator_get_next
    _result = pywrap_tfe.TFE_Py_FastPathExecute(
UnicodeDecodeError: 'utf-8' codec can't decode byte 0xd5 in position 211: invalid continuation byte
Restored from D:\HAR\experiments\run_2024-01-28T19-28-59-232815\ckpts\ckpt-24
111
222
333